Workbook

Sheet FBMS-HND LEVEL TWO (2) FREQ
A1: Catholic University of Cameroon, CATUC, Bamenda
A2: Faculty of business & Management Sciences-HND
A3: First Semester Exam 2023-2024
A4: Department: | B4: Common course
A5: Course Code | B5: FRE 2101
A6: Course Title | B6: Functional French III
A7: Credit Value | B7: 2
A8: Lecturer | B8: Dr Ngoran George
A9: Level: 2 | B9: HND/FBMS 2 | L9: Grades | M9: Remarks | N9: STATISTICS
A10: S/N | B10: MAT. NO | C10: NAME | D10: Exam Codes | E10: Att/10 | F10: CA/30 | G10: Tot/40 | H10: sign in | I10: sign out | J10: Exam/60 | K10: Total/100 | N10: No. Registered | O10: =COUNT(G12:G65) -> 48
A11: Common Course | N11: No. Examined | O11: =COUNT(J12:J65) -> 45
A12: =ROW(A1) -> 1 | B12: 338222H | C12: Abdou Ziena Madinatou | D12: FRE 2101/17 | E12: 8 | F12: 23 | G12: =SUM(E12:F12) -> 31 | J12: 26 | K12: =SUM(G12:J12) -> 57 | L12: =IF(K12>=80,"A",IF(K12>=70,"B+",IF(K12>=60,"B",IF(K12>=55,"C+",IF(K12>=50,"C",IF(K12>=45,"D+",IF(K12>=40,"D","F"))))))) -> C+ | M12: =IF(K12>=50,"Passed","Failed") -> Passed | N12: No . ABS | O12: =O10-O11 -> 3
A13: =ROW(A2) -> 2 | B13: 330322H | C13: Acha Victory Nweyeh-kah | D13: FRE 2101/44 | E13: 8 | F13: 19 | G13: =SUM(E13:F13) -> 27 | J13: 26 | K13: =SUM(G13:J13) -> 53 | L13: =IF(K13>=80,"A",IF(K13>=70,"B+",IF(K13>=60,"B",IF(K13>=55,"C+",IF(K13>=50,"C",IF(K13>=45,"D+",IF(K13>=40,"D","F"))))))) -> C | M13: =IF(K13>=50,"Passed","Failed") -> Passed | N13: No. Passed | O13: =COUNTIF(M12:M65,"Passed") -> 33
A14: =ROW(A3) -> 3 | B14: 340822H | C14: Akang Courage Bi | D14: FRE 2101/12 | E14: 8 | F14: 23 | G14: =SUM(E14:F14) -> 31 | J14: 28 | K14: =SUM(G14:J14) -> 59 | L14: =IF(K14>=80,"A",IF(K14>=70,"B+",IF(K14>=60,"B",IF(K14>=55,"C+",IF(K14>=50,"C",IF(K14>=45,"D+",IF(K14>=40,"D","F"))))))) -> C+ | M14: =IF(K14>=50,"Passed","Failed") -> Passed | N14: % Pass | O14: =O13/O11% -> 73.333333
A15: =ROW(A4) -> 4 | B15: 340922H | C15: Awah Priddy Mboh-Ngeh | D15: FRE 2101/34 | E15: 8 | F15: 20 | G15: =SUM(E15:F15) -> 28 | J15: 20 | K15: =SUM(G15:J15) -> 48 | L15: =IF(K15>=80,"A",IF(K15>=70,"B+",IF(K15>=60,"B",IF(K15>=55,"C+",IF(K15>=50,"C",IF(K15>=45,"D+",IF(K15>=40,"D","F"))))))) -> D+ | M15: =IF(K15>=50,"Passed","Failed") -> Failed | N15: No. Failed | O15: =COUNTIF(M12:M65,"failed") -> 12
A16: =ROW(A5) -> 5 | B16: 330522H | C16: Bin Abigael Nwa | D16: FRE 2101/21 | E16: 8 | F16: 26 | G16: =SUM(E16:F16) -> 34 | J16: 32 | K16: =SUM(G16:J16) -> 66 | L16: =IF(K16>=80,"A",IF(K16>=70,"B+",IF(K16>=60,"B",IF(K16>=55,"C+",IF(K16>=50,"C",IF(K16>=45,"D+",IF(K16>=40,"D","F"))))))) -> B | M16: =IF(K16>=50,"Passed","Failed") -> Passed | N16: % Failed | O16: =O15/O11% -> 26.666667
A17: =ROW(A6) -> 6 | B17: 337322H | C17: Famah Shamah Nfor | D17: FRE 2101/11 | E17: 8 | F17: 21 | G17: =SUM(E17:F17) -> 29 | J17: 26 | K17: =SUM(G17:J17) -> 55 | L17: =IF(K17>=80,"A",IF(K17>=70,"B+",IF(K17>=60,"B",IF(K17>=55,"C+",IF(K17>=50,"C",IF(K17>=45,"D+",IF(K17>=40,"D","F"))))))) -> C+ | M17: =IF(K17>=50,"Passed","Failed") -> Passed | N17: Course Average | O17: =AVERAGE(K12:K65) -> 54.177778
A18: =ROW(A7) -> 7 | B18: 360022H | C18: Favour Bongnavti Aloni | D18: FRE 2101/
A19: =ROW(A8) -> 8 | B19: 345122H | C19: Fri Jenifer Chick | D19: FRE 2101/32 | E19: 8 | F19: 22 | G19: =SUM(E19:F19) -> 30 | J19: 24 | K19: =SUM(G19:J19) -> 54 | L19: =IF(K19>=80,"A",IF(K19>=70,"B+",IF(K19>=60,"B",IF(K19>=55,"C+",IF(K19>=50,"C",IF(K19>=45,"D+",IF(K19>=40,"D","F"))))))) -> C | M19: =IF(K19>=50,"Passed","Failed") -> Passed
A20: =ROW(A9) -> 9 | B20: 329522H | C20: Hawa Amira Ibrahim | D20: FRE 2101/37 | E20: 8 | F20: 21 | G20: =SUM(E20:F20) -> 29 | J20: 42 | K20: =SUM(G20:J20) -> 71 | L20: =IF(K20>=80,"A",IF(K20>=70,"B+",IF(K20>=60,"B",IF(K20>=55,"C+",IF(K20>=50,"C",IF(K20>=45,"D+",IF(K20>=40,"D","F"))))))) -> B+ | M20: =IF(K20>=50,"Passed","Failed") -> Passed | N20: Grades
A21: =ROW(A10) -> 10 | B21: 352522H | C21: Mbuya Excel Ngeh | D21: FRE 2101/15 | E21: 8 | F21: 12 | G21: =SUM(E21:F21) -> 20 | J21: 8 | K21: =SUM(G21:J21) -> 28 | L21: =IF(K21>=80,"A",IF(K21>=70,"B+",IF(K21>=60,"B",IF(K21>=55,"C+",IF(K21>=50,"C",IF(K21>=45,"D+",IF(K21>=40,"D","F"))))))) -> F | M21: =IF(K21>=50,"Passed","Failed") -> Failed | O21: A | P21: B+ | Q21: B | R21: C+ | S21: C | T21: D+ | U21: D | V21: F
A22: =ROW(A11) -> 11 | B22: 320021H | C22: Muna Beltus | D22: FRE 2101/ | O22: =COUNTIF(L12:L65,"A") -> 0 | P22: =COUNTIF(L12:L65,"B+") -> 2 | Q22: =COUNTIF(L12:L65,"B") -> 9 | R22: =COUNTIF(L12:L65,"C+") -> 9 | S22: =COUNTIF(L12:L65,"C") -> 13 | T22: =COUNTIF(L12:L65,"D+") -> 6 | U22: =COUNTIF(L12:L65,"D") -> 5 | V22: =COUNTIF(L12:L65,"F") -> 1
A23: =ROW(A12) -> 12 | B23: 330422H | C23: Nde Cindy-Bright Luh | D23: FRE 2101/3 | E23: 8 | F23: 19 | G23: =SUM(E23:F23) -> 27 | J23: 31 | K23: =SUM(G23:J23) -> 58 | L23: =IF(K23>=80,"A",IF(K23>=70,"B+",IF(K23>=60,"B",IF(K23>=55,"C+",IF(K23>=50,"C",IF(K23>=45,"D+",IF(K23>=40,"D","F"))))))) -> C+ | M23: =IF(K23>=50,"Passed","Failed") -> Passed
A24: =ROW(A13) -> 13 | B24: 337922H | C24: Ndukong Seraphine Mangwang | D24: FRE 2101/8 | E24: 8 | F24: 15 | G24: =SUM(E24:F24) -> 23 | J24: 31 | K24: =SUM(G24:J24) -> 54 | L24: =IF(K24>=80,"A",IF(K24>=70,"B+",IF(K24>=60,"B",IF(K24>=55,"C+",IF(K24>=50,"C",IF(K24>=45,"D+",IF(K24>=40,"D","F"))))))) -> C | M24: =IF(K24>=50,"Passed","Failed") -> Passed
A25: 14 | B25: 341722H | C25: Nformi Christabella | D25: FRE 2101/46 | E25: 8 | F25: 15 | G25: =SUM(E25:F25) -> 23 | J25: 19 | K25: =SUM(G25:J25) -> 42 | L25: =IF(K25>=80,"A",IF(K25>=70,"B+",IF(K25>=60,"B",IF(K25>=55,"C+",IF(K25>=50,"C",IF(K25>=45,"D+",IF(K25>=40,"D","F"))))))) -> D | M25: =IF(K25>=50,"Passed","Failed") -> Failed
A26: =ROW(A15) -> 15 | B26: 347622H | C26: Ngam Hedwig Afumbom | D26: FRE 2101/47 | E26: 8 | F26: 20 | G26: =SUM(E26:F26) -> 28 | J26: 21 | K26: =SUM(G26:J26) -> 49 | L26: =IF(K26>=80,"A",IF(K26>=70,"B+",IF(K26>=60,"B",IF(K26>=55,"C+",IF(K26>=50,"C",IF(K26>=45,"D+",IF(K26>=40,"D","F"))))))) -> D+ | M26: =IF(K26>=50,"Passed","Failed") -> Failed
A27: =ROW(A16) -> 16 | B27: 329422H | C27: Ngwa Joseph Neba | D27: FRE 2101/20 | E27: 8 | F27: 18 | G27: =SUM(E27:F27) -> 26 | J27: 14 | K27: =SUM(G27:J27) -> 40 | L27: =IF(K27>=80,"A",IF(K27>=70,"B+",IF(K27>=60,"B",IF(K27>=55,"C+",IF(K27>=50,"C",IF(K27>=45,"D+",IF(K27>=40,"D","F"))))))) -> D | M27: =IF(K27>=50,"Passed","Failed") -> Failed
A28: =ROW(A17) -> 17 | B28: 350122H | C28: Nyuydzewira Lorantine Shuka | D28: FRE 2101/16 | E28: 8 | F28: 21 | G28: =SUM(E28:F28) -> 29 | J28: 32 | K28: =SUM(G28:J28) -> 61 | L28: =IF(K28>=80,"A",IF(K28>=70,"B+",IF(K28>=60,"B",IF(K28>=55,"C+",IF(K28>=50,"C",IF(K28>=45,"D+",IF(K28>=40,"D","F"))))))) -> B | M28: =IF(K28>=50,"Passed","Failed") -> Passed
A29: =ROW(A18) -> 18 | B29: 367522H | C29: Samnissi Rawllings Galabe | D29: FRE 2101/2
A30: =ROW(A19) -> 19 | B30: 335622H | C30: Stercy Megan Agbor | D30: FRE 2101/26
A31: =ROW(A20) -> 20 | B31: 347022H | C31: Suzyl Wiyrdzernyuy | D31: FRE 2101/36 | E31: 8 | F31: 30 | G31: =SUM(E31:F31) -> 38 | J31: 27 | K31: =SUM(G31:J31) -> 65 | L31: =IF(K31>=80,"A",IF(K31>=70,"B+",IF(K31>=60,"B",IF(K31>=55,"C+",IF(K31>=50,"C",IF(K31>=45,"D+",IF(K31>=40,"D","F"))))))) -> B | M31: =IF(K31>=50,"Passed","Failed") -> Passed
A32: =ROW(A21) -> 21 | B32: 337222H | C32: Tah Marceline Kemaka | D32: FRE 2101/9 | E32: 8 | F32: 18 | G32: =SUM(E32:F32) -> 26 | J32: 27 | K32: =SUM(G32:J32) -> 53 | L32: =IF(K32>=80,"A",IF(K32>=70,"B+",IF(K32>=60,"B",IF(K32>=55,"C+",IF(K32>=50,"C",IF(K32>=45,"D+",IF(K32>=40,"D","F"))))))) -> C | M32: =IF(K32>=50,"Passed","Failed") -> Passed
A33: =ROW(A22) -> 22 | B33: 344522H | C33: Yirenwie-Mado Favour Munjere | D33: FRE 2101/14 | E33: 8 | F33: 19 | G33: =SUM(E33:F33) -> 27 | J33: 33 | K33: =SUM(G33:J33) -> 60 | L33: =IF(K33>=80,"A",IF(K33>=70,"B+",IF(K33>=60,"B",IF(K33>=55,"C+",IF(K33>=50,"C",IF(K33>=45,"D+",IF(K33>=40,"D","F"))))))) -> B | M33: =IF(K33>=50,"Passed","Failed") -> Passed
A34: =ROW(A23) -> 23 | B34: 334522H | C34: Ntungwen Brian | D34: FRE 2101/31 | E34: 8 | F34: 18 | G34: =SUM(E34:F34) -> 26 | J34: 26 | K34: =SUM(G34:J34) -> 52 | L34: =IF(K34>=80,"A",IF(K34>=70,"B+",IF(K34>=60,"B",IF(K34>=55,"C+",IF(K34>=50,"C",IF(K34>=45,"D+",IF(K34>=40,"D","F"))))))) -> C | M34: =IF(K34>=50,"Passed","Failed") -> Passed
A35: =ROW(A24) -> 24 | B35: 341822H | C35: Ajeakwa Keziah Umenek | D35: FRE 2101/22 | E35: 8 | F35: 16 | G35: =SUM(E35:F35) -> 24 | J35: 16 | K35: =SUM(G35:J35) -> 40 | L35: =IF(K35>=80,"A",IF(K35>=70,"B+",IF(K35>=60,"B",IF(K35>=55,"C+",IF(K35>=50,"C",IF(K35>=45,"D+",IF(K35>=40,"D","F"))))))) -> D | M35: =IF(K35>=50,"Passed","Failed") -> Failed
A36: =ROW(A25) -> 25 | B36: 335722H | C36: Bih Larissa Ngang | D36: FRE 2101/48 | E36: 8 | F36: 20 | G36: =SUM(E36:F36) -> 28 | J36: 34 | K36: =SUM(G36:J36) -> 62 | L36: =IF(K36>=80,"A",IF(K36>=70,"B+",IF(K36>=60,"B",IF(K36>=55,"C+",IF(K36>=50,"C",IF(K36>=45,"D+",IF(K36>=40,"D","F"))))))) -> B | M36: =IF(K36>=50,"Passed","Failed") -> Passed
A37: =ROW(A26) -> 26 | B37: 341522H | C37: Bih Mary-Ann Anchimbom Lainsi | D37: FRE 2101/10 | E37: 8 | F37: 22 | G37: =SUM(E37:F37) -> 30 | J37: 28 | K37: =SUM(G37:J37) -> 58 | L37: =IF(K37>=80,"A",IF(K37>=70,"B+",IF(K37>=60,"B",IF(K37>=55,"C+",IF(K37>=50,"C",IF(K37>=45,"D+",IF(K37>=40,"D","F"))))))) -> C+ | M37: =IF(K37>=50,"Passed","Failed") -> Passed
A38: =ROW(A27) -> 27 | B38: 328522H | C38: Formari Marion Mah | D38: FRE 2101/13 | E38: 8 | F38: 26 | G38: =SUM(E38:F38) -> 34 | J38: 14 | K38: =SUM(G38:J38) -> 48 | L38: =IF(K38>=80,"A",IF(K38>=70,"B+",IF(K38>=60,"B",IF(K38>=55,"C+",IF(K38>=50,"C",IF(K38>=45,"D+",IF(K38>=40,"D","F"))))))) -> D+ | M38: =IF(K38>=50,"Passed","Failed") -> Failed
A39: =ROW(A28) -> 28 | B39: 341022H | C39: Frou Excel Esepene | D39: FRE 2101/29 | E39: 8 | F39: 18 | G39: =SUM(E39:F39) -> 26 | J39: 24 | K39: =SUM(G39:J39) -> 50 | L39: =IF(K39>=80,"A",IF(K39>=70,"B+",IF(K39>=60,"B",IF(K39>=55,"C+",IF(K39>=50,"C",IF(K39>=45,"D+",IF(K39>=40,"D","F"))))))) -> C | M39: =IF(K39>=50,"Passed","Failed") -> Passed
A40: =ROW(A29) -> 29 | B40: 332422H | C40: Kemeng Marigiselle Nteinmussi | D40: FRE 2101/18 | E40: 8 | F40: 21 | G40: =SUM(E40:F40) -> 29 | J40: 35 | K40: =SUM(G40:J40) -> 64 | L40: =IF(K40>=80,"A",IF(K40>=70,"B+",IF(K40>=60,"B",IF(K40>=55,"C+",IF(K40>=50,"C",IF(K40>=45,"D+",IF(K40>=40,"D","F"))))))) -> B | M40: =IF(K40>=50,"Passed","Failed") -> Passed
...

Sheet Sheet1 (2)
C1: CATHOLIC UNIVERSITY OF CAMEROON (CATUC), BAMENDA
A3: SCHOOL/ FACULTY: FACULTY OF SCIENCE | C3: BUSINESS AND MANAGEMENT SCIENCES | L3: COMMON COURSES
L4: SEMESTER: FIRST SEMESTER
A5: HND | L5: SCHOOL YEAR: 2023/2024
C7: FREQUENCY DISTRIBUTION PERFORMANCES OF STUDENTS
A8: SN | B8: COURSE CODE | C8: COURSE TITLE | D8: CV | E8: ST | F8: LECTURERS | G8: % CC | H8: NUMBER | L8: % PASS | M8: % FAIL | N8: NUMBER
H9: CR | I9: CE | J9: PASSED | K9: FAILED | N9: A | O9: B+ | P9: B | Q9: C+ | R9: C | S9: D+ | T9: D | U9: F
A10: 1 | B10: ='[1]level one'!$C$94 -> INS1101H | C10: ='[1]level one'!$C$95 -> Principles of Insurance | D10: ='[1]level one'!$C$96 -> 3 | E10: C | F10: Mme. Lukong Claris | G10: 86 | H10: ='FBMS-HND LEVEL ONE'!$O$163 -> 54 | I10: ='FBMS-HND LEVEL ONE'!$O$164 -> 54 | J10: ='FBMS-HND LEVEL ONE'!$O$166 -> 40 | K10: ='FBMS-HND LEVEL ONE'!$O$168 -> 14 | L10: ='FBMS-HND LEVEL ONE'!$O$167 -> 74.074074 | M10: =K10/I10*100 -> 25.925926 | N10: ='FBMS-HND LEVEL ONE'!O175 -> 1 | O10: ='FBMS-HND LEVEL ONE'!P175 -> 6 | P10: ='FBMS-HND LEVEL ONE'!Q175 -> 14 | Q10: ='FBMS-HND LEVEL ONE'!R175 -> 6 | R10: ='FBMS-HND LEVEL ONE'!S175 -> 13 | S10: ='FBMS-HND LEVEL ONE'!T175 -> 3 | T10: ='FBMS-HND LEVEL ONE'!U175 -> 3 | U10: ='FBMS-HND LEVEL ONE'!V175 -> 8 | V10: =SUM(N10:U10) -> 54
A11: 2 | B11: ='[1]level one'!$C$296 -> ENG1101H | C11: ='[1]level one'!$C$297 -> Functional English I | D11: ='[1]level one'!$C$298 -> 2 | E11: C | F11: ='[1]level one'!$C$299 -> Dr Ngie Florence | G11: 100 | H11: 150 | I11: 145 | J11: 145 | K11: 0 | L11: =J11/I11*100 -> 100 | M11: =K11/I11*100 -> 0 | N11: 3 | O11: 50 | P11: 60 | Q11: 20 | R11: 12 | S11: 0 | T11: 0 | U11: 0 | V11: =SUM(N11:U11) -> 145
A12: 3 | B12: FRE1101H | C12: Functional French I | D12: 2 | E12: C | F12: Dr.Ngoran George | G12: 100 | H12: 148 | I12: 144 | J12: 117 | K12: 27 | L12: =J12/I12*100 -> 81.25 | M12: =K12/I12*100 -> 18.75 | N12: 10 | O12: 33 | P12: 61 | Q12: 7 | R12: 6 | S12: 10 | T12: 9 | U12: 8 | V12: =SUM(N12:U12) -> 144
A13: 4 | B13: ='[1]level two'!$C$36 -> ENG 2101H | C13: ='[1]level two'!$C$37 -> Functional English III | D13: ='[1]level two'!$C$38 -> 2 | E13: C | F13: ='[1]level two'!$C$39 -> Dr. Ngie Florence | G13: 100 | H13: 111 | I13: 108 | J13: 104 | K13: 4 | L13: =J13/I13*100 -> 96.296296 | M13: =K13/I13*100 -> 3.7037037 | N13: 13 | O13: 32 | P13: 42 | Q13: 10 | R13: 7 | S13: 1 | T13: 2 | U13: 1 | V13: =SUM(N13:U13) -> 108
A14: 5 | B14: FRE 2101H | C14: Functional French III | D14: 2 | E14: C | F14: Dr.Ngoran George | G14: 100 | H14: 107 | I14: 103 | J14: 58 | K14: 45 | L14: =J14/I14*100 -> 56.31068 | M14: =K14/I14*100 -> 43.68932 | N14: 1 | O14: 4 | P14: 16 | Q14: 18 | R14: 19 | S14: 17 | T14: 17 | U14: 11 | V14: =SUM(N14:U14) -> 103
A15: 6 | B15: ='[1]level two'!$C$141 -> COM 2101H | C15: ='[1]level two'!$C$142 -> Computer Science | D15: ='[1]level two'!$C$143 -> 2 | E15: C | F15: ='FBMS-HND LEVEL TWO'!$B$291 -> Mr.Nkeng Blaise | G15: 80 | H15: 111 | I15: 108 | J15: 84 | K15: 24 | L15: =J15/I15*100 -> 77.777778 | M15: =K15/I15*100 -> 22.222222 | N15: 4 | O15: 8 | P15: 34 | Q15: 17 | R15: 21 | S15: 13 | T15: 6 | U15: 5 | V15: =SUM(N15:U15) -> 108
A16: 7 | B16: ='[1]level one'!$C$245 -> ECO1101H | C16: ='[1]level one'!$C$246 -> Principles of Micro-economics | D16: ='[1]level one'!$C$247 -> 2 | E16: C | F16: Mr Kedju Robert Nembo | G16: 90 | H16: ='FBMS-HND LEVEL ONE'!$O$375 -> 54 | I16: ='FBMS-HND LEVEL ONE'!$O$376 -> 54 | J16: ='FBMS-HND LEVEL ONE'!$O$378 -> 44 | K16: ='FBMS-HND LEVEL ONE'!$O$380 -> 10 | L16: =J16/I16*100 -> 81.481481 | M16: =K16/I16*100 -> 18.518519 | N16: ='FBMS-HND LEVEL ONE'!O386 -> 8 | O16: ='FBMS-HND LEVEL ONE'!P386 -> 7 | P16: ='FBMS-HND LEVEL ONE'!Q386 -> 13 | Q16: ='FBMS-HND LEVEL ONE'!R386 -> 7 | R16: ='FBMS-HND LEVEL ONE'!S386 -> 9 | S16: ='FBMS-HND LEVEL ONE'!T386 -> 3 | T16: ='FBMS-HND LEVEL ONE'!U386 -> 3 | U16: ='FBMS-HND LEVEL ONE'!V386 -> 4 | V16: =SUM(N16:U16) -> 54
A17: 8 | B17: ='[1]level one'!$C$349 -> ECO1102H | C17: ='[1]level one'!$C$350 -> Statuistics and Business Mathematicss | D17: ='[1]level one'!$C$351 -> 2 | E17: C | F17: Mme. Lukong Claris | G17: 92 | H17: ='FBMS-HND LEVEL ONE'!$O$529 -> 56 | I17: ='FBMS-HND LEVEL ONE'!$O$530 -> 55 | J17: ='FBMS-HND LEVEL ONE'!$O$532 -> 43 | K17: ='FBMS-HND LEVEL ONE'!$O$534 -> 12 | L17: =J17/I17*100 -> 78.181818 | M17: =K17/I17*100 -> 21.818182 | N17: ='FBMS-HND LEVEL ONE'!O541 -> 5 | O17: ='FBMS-HND LEVEL ONE'!P541 -> 7 | P17: ='FBMS-HND LEVEL ONE'!Q541 -> 14 | Q17: ='FBMS-HND LEVEL ONE'!R541 -> 6 | R17: ='FBMS-HND LEVEL ONE'!S541 -> 11 | S17: ='FBMS-HND LEVEL ONE'!T541 -> 1 | T17: ='FBMS-HND LEVEL ONE'!U541 -> 4 | U17: ='FBMS-HND LEVEL ONE'!V541 -> 7 | V17: =SUM(N17:U17) -> 55
A18: 9 | B18: MAT1101H | C18: Elementary Mathematics | D18: 2 | E18: C | F18: Mr Muokweh Julius | G18: 100 | H18: ='FBMS-HND LEVEL ONE'!$O$453 -> 54 | I18: ='FBMS-HND LEVEL ONE'!$O$454 -> 54 | J18: ='FBMS-HND LEVEL ONE'!$O$456 -> 53 | K18: ='FBMS-HND LEVEL ONE'!$O$458 -> 1 | L18: =J18/I18*100 -> 98.148148 | M18: =K18/I18*100 -> 1.8518519 | N18: ='FBMS-HND LEVEL ONE'!O465 -> 6 | O18: ='FBMS-HND LEVEL ONE'!P465 -> 7 | P18: ='FBMS-HND LEVEL ONE'!Q465 -> 16 | Q18: ='FBMS-HND LEVEL ONE'!R465 -> 10 | R18: ='FBMS-HND LEVEL ONE'!S465 -> 14 | S18: ='FBMS-HND LEVEL ONE'!T465 -> 1 | T18: ='FBMS-HND LEVEL ONE'!U465 -> 0 | U18: ='FBMS-HND LEVEL ONE'!V465 -> 0 | V18: =SUM(N18:U18) -> 54
A19: 10 | B19: ='[1]level two'!$C$207 -> ECO 2101H | C19: ='[1]level two'!$C$208 -> Managerial Economics | D19: ='[1]level two'!$C$209 -> 2 | E19: C | F19: Mr Kedju Robert Nembo | G19: 80 | H19: ='FBMS-HND LEVEL TWO'!$O$421 -> 49 | I19: ='FBMS-HND LEVEL TWO'!$O$422 -> 47 | J19: ='FBMS-HND LEVEL TWO'!$O$424 -> 46 | K19: ='FBMS-HND LEVEL TWO'!$O$426 -> 1 | L19: =J19/I19*100 -> 97.87234 | M19: =K19/I19*100 -> 2.1276596 | N19: ='FBMS-HND LEVEL TWO'!O433 -> 15 | O19: ='FBMS-HND LEVEL TWO'!P433 -> 13 | P19: ='FBMS-HND LEVEL TWO'!Q433 -> 9 | Q19: ='FBMS-HND LEVEL TWO'!R433 -> 4 | R19: ='FBMS-HND LEVEL TWO'!S433 -> 5 | S19: ='FBMS-HND LEVEL TWO'!T433 -> 0 | T19: ='FBMS-HND LEVEL TWO'!U433 -> 0 | U19: ='FBMS-HND LEVEL TWO'!V433 -> 1 | V19: =SUM(N19:U19) -> 47
A20: 11 | B20: ='[1]level two'!$C$70 -> ECO 2102H | C20: Statistics and Business Mathematics III | D20: ='[1]level two'!$C$72 -> 2 | E20: C | F20: Mr Ghondo charles | G20: 100 | H20: ='FBMS-HND LEVEL TWO'!$O$148 -> 51 | I20: ='FBMS-HND LEVEL TWO'!$O$149 -> 49 | J20: ='FBMS-HND LEVEL TWO'!$O$151 -> 49 | K20: ='FBMS-HND LEVEL TWO'!$O$153 -> 0 | L20: =J20/I20*100 -> 100 | M20: =K20/I20*100 -> 0 | N20: ='FBMS-HND LEVEL TWO'!O158 -> 2 | O20: ='FBMS-HND LEVEL TWO'!P158 -> 13 | P20: ='FBMS-HND LEVEL TWO'!Q158 -> 25 | Q20: ='FBMS-HND LEVEL TWO'!R158 -> 8 | R20: ='FBMS-HND LEVEL TWO'!S158 -> 1 | S20: ='FBMS-HND LEVEL TWO'!T158 -> 0 | T20: ='FBMS-HND LEVEL TWO'!U158 -> 0 | U20: ='FBMS-HND LEVEL TWO'!V158 -> 0 | V20: =SUM(N20:U20) -> 49
A21: 12 | B21: MGT 2207H | C21: Enterprise Creation and Entrepreneurship | D21: 3 | E21: C | F21: Mr Ghondo charles | G21: 90 | H21: 90 | I21: 90 | J21: 85 | K21: 5 | L21: =J21/I21*100 -> 94.444444 | M21: =K21/I21*100 -> 5.5555556 | N21: 27 | O21: 33 | P21: 15 | Q21: 8 | R21: 2 | S21: 1 | T21: 2 | U21: 2 | V21: =SUM(N21:U21) -> 90
C22: TOTAL/ AVERAGE | H22: =SUM(H10:H21) -> 1035 | I22: =SUM(I10:I21) -> 1011 | J22: =SUM(J10:J21) -> 868 | K22: =SUM(K10:K21) -> 143 | L22: =J22/I22*100 -> 85.855589 | M22: =K22/I22*100 -> 14.144411 | N22: =SUM(N10:N21) -> 95 | O22: =SUM(O10:O21) -> 213 | P22: =SUM(P10:P21) -> 319 | Q22: =SUM(Q10:Q21) -> 121 | R22: =SUM(R10:R21) -> 120 | S22: =SUM(S10:S21) -> 50 | T22: =SUM(T10:T21) -> 46 | U22: =SUM(U10:U21) -> 47 | V22: =SUM(N22:U22) -> 1011
B23: CV = Credit Value; ST = Status (C = Compulsory; E = Elective); CR = Candidates Registered; CE = Candidates Examined; % CC = Course Coverage; The % Pass is based on CE (Candidates who completed the course by writing the final examination.
B25: Number of Marked Scripts: | D25: =$I$22 -> 1011 | I25: Number of Failed Scripts | N25: =$K$22 -> 143
B27: Number of Passed Scripts | D27: =$J$22 -> 868
I28: Success Rate | M28: =$L$22 -> 85.855589
A29: Lecturers:
C31: =$F$10 -> Mme. Lukong Claris | K31: =$F$11 -> Dr Ngie Florence | P31: =$F$15 -> Mr.Nkeng Blaise
C35: Sr. Elizabeth Ankiambom | E35: Dr. | F35: Achiri Mongo Eric
C36: HND Cordinator | F36: Dean-FBMS-HND
C49: CATHOLIC UNIVERSITY OF CAMEROON (CATUC), BAMENDA
A51: SCHOOL/ FACULTY: FACULTY OF SCIENCE | C51: BUSINESS AND MANAGEMENT SCIENCES | L51: DEPARTMENT: ACCOUNTING
L52: SEMESTER: FIRST SEMESTER
A53: HND | L53: SCHOOL YEAR: 2023/2024
C55: FREQUENCY DISTRIBUTION PERFORMANCES OF STUDENTS
A56: SN | B56: COURSE CODE | C56: COURSE TITLE | D56: CV | E56: ST | F56: LECTURERS | G56: % CC | H56: NUMBER | L56: % PASS | M56: % FAIL | N56: NUMBER
H57: CR | I57: CE | J57: PASSED | K57: FAILED | N57: A | O57: B+ | P57: B | Q57: C+ | R57: C | S57: D+ | T57: D | U57: F
A58: 1 | B58: ='[1]level one'!$C$402 -> ACC1102H | C58: ='[1]level one'!$C$403 -> OHADA Financial Accounting I | D58: 3 | E58: C | F58: Mr.Ngondo Charles | G58: 80 | H58: ='FBMS-HND LEVEL ONE'!$O$599 -> 54 | I58: ='FBMS-HND LEVEL ONE'!$O$600 -> 54 | J58: ='FBMS-HND LEVEL ONE'!$O$602 -> 50 | K58: ='FBMS-HND LEVEL ONE'!$O$604 -> 4 | L58: =J58/I58*100 -> 92.592593 | M58: =K58/I58*100 -> 7.4074074 | N58: ='FBMS-HND LEVEL ONE'!O612 -> 3 | O58: ='FBMS-HND LEVEL ONE'!P612 -> 12 | P58: ='FBMS-HND LEVEL ONE'!Q612 -> 23 | Q58: ='FBMS-HND LEVEL ONE'!R612 -> 5 | R58: ='FBMS-HND LEVEL ONE'!S612 -> 7 | S58: ='FBMS-HND LEVEL ONE'!T612 -> 1 | T58: ='FBMS-HND LEVEL ONE'!U612 -> 2 | U58: ='FBMS-HND LEVEL ONE'!V612 -> 1 | V58: =SUM(N58:U58) -> 54
A59: 2 | B59: ACC1105H | C59: ='[1]level one'!$C$458 -> Principles of Taxation | D59: ='[1]level one'!$C$459 -> 3 | E59: C | F59: ='[1]level one'!$C$460 -> Mr Youopouo Maurice | G59: 86 | H59: ='FBMS-HND LEVEL ONE'!$O$670 -> 54 | I59: ='FBMS-HND LEVEL ONE'!$O$671 -> 54 | J59: ='FBMS-HND LEVEL ONE'!$O$673 -> 39 | K59: ='FBMS-HND LEVEL ONE'!$O$675 -> 15 | L59: =J59/I59*100 -> 72.222222 | M59: =K59/I59*100 -> 27.777778 | N59: ='FBMS-HND LEVEL ONE'!O682 -> 3 | O59: ='FBMS-HND LEVEL ONE'!P682 -> 9 | P59: ='FBMS-HND LEVEL ONE'!Q682 -> 12 | Q59: ='FBMS-HND LEVEL ONE'!R682 -> 8 | R59: ='FBMS-HND LEVEL ONE'!S682 -> 7 | S59: ='FBMS-HND LEVEL ONE'!T682 -> 0 | T59: ='FBMS-HND LEVEL ONE'!U682 -> 1 | U59: ='FBMS-HND LEVEL ONE'!V682 -> 14 | V59: =SUM(N59:U59) -> 54
A60: 3 | B60: ='[1]level one'!$C$563 -> ACC1101H | C60: ='[1]level one'!$C$564 -> Principles of Accounting | D60: ='[1]level one'!$C$565 -> 3 | E60: C | F60: Mr Nzebir Chrysantus | G60: 80 | H60: ='FBMS-HND LEVEL ONE'!$O$813 -> 56 | I60: ='FBMS-HND LEVEL ONE'!$O$814 -> 55 | J60: ='FBMS-HND LEVEL ONE'!$O$816 -> 41 | K60: ='FBMS-HND LEVEL ONE'!$O$818 -> 14 | L60: =J60/I60*100 -> 74.545455 | M60: =K60/I60*100 -> 25.454545 | N60: ='FBMS-HND LEVEL ONE'!O826 -> 9 | O60: ='FBMS-HND LEVEL ONE'!P826 -> 14 | P60: ='FBMS-HND LEVEL ONE'!Q826 -> 7 | Q60: ='FBMS-HND LEVEL ONE'!R826 -> 4 | R60: ='FBMS-HND LEVEL ONE'!S826 -> 7 | S60: ='FBMS-HND LEVEL ONE'!T826 -> 2 | T60: ='FBMS-HND LEVEL ONE'!U826 -> 3 | U60: ='FBMS-HND LEVEL ONE'!V826 -> 9 | V60: =SUM(N60:U60) -> 55
A61: 4 | B61: ='[1]level two'!$C$104 -> ACC 2103H | C61: ='[1]level two'!$C$105 -> Cost & Management Accounting II | D61: ='[1]level two'!$C$106 -> 3 | E61: C | F61: Mr.Shiyghan Chrysanctus | G61: 86 | H61: ='FBMS-HND LEVEL TWO'!$O$221 -> 50 | I61: ='FBMS-HND LEVEL TWO'!$O$222 -> 49 | J61: ='FBMS-HND LEVEL TWO'!$O$224 -> 39 | K61: ='FBMS-HND LEVEL TWO'!$O$226 -> 10 | L61: =J61/I61*100 -> 79.591837 | M61: =K61/I61*100 -> 20.408163 | N61: ='FBMS-HND LEVEL TWO'!O233 -> 9 | O61: ='FBMS-HND LEVEL TWO'!P233 -> 4 | P61: ='FBMS-HND LEVEL TWO'!Q233 -> 19 | Q61: ='FBMS-HND LEVEL TWO'!R233 -> 2 | R61: ='FBMS-HND LEVEL TWO'!S233 -> 5 | S61: ='FBMS-HND LEVEL TWO'!T233 -> 2 | T61: ='FBMS-HND LEVEL TWO'!U233 -> 4 | U61: ='FBMS-HND LEVEL TWO'!V233 -> 4 | V61: =SUM(N61:U61) -> 49
A62: 5 | B62: ='[1]level two'!$C$174 -> ACC 2105H | C62: ='[1]level two'!$C$175 -> Taxation I & II | D62: ='[1]level two'!$C$176 -> 3 | E62: C | F62: ='[1]level two'!$C$177 -> Mr. Youopouo Maurice | G62: 100 | H62: ='FBMS-HND LEVEL TWO'!$O$370 -> 29 | I62: ='FBMS-HND LEVEL TWO'!$O$371 -> 29 | J62: ='FBMS-HND LEVEL TWO'!$O$373 -> 25 | K62: ='FBMS-HND LEVEL TWO'!$O$375 -> 4 | L62: =J62/I62*100 -> 86.206897 | M62: =K62/I62*100 -> 13.793103 | N62: ='FBMS-HND LEVEL TWO'!O382 -> 5 | O62: ='FBMS-HND LEVEL TWO'!P382 -> 2 | P62: ='FBMS-HND LEVEL TWO'!Q382 -> 8 | Q62: ='FBMS-HND LEVEL TWO'!R382 -> 4 | R62: ='FBMS-HND LEVEL TWO'!S382 -> 6 | S62: ='FBMS-HND LEVEL TWO'!T382 -> 0 | T62: ='FBMS-HND LEVEL TWO'!U382 -> 2 | U62: ='FBMS-HND LEVEL TWO'!V382 -> 2 | V62: =SUM(N62:U62) -> 29
...

Sheet FBMS-HND LEVEL ONE
A1: Catholic University of Cameroon, CATUC, Bamenda
A2: Faculty of Business and Management Science-HND
A3: First Semester Exam 2023-2024
A4: Department: | C4: HND 1
A5: Course Code | C5: BFI1101H
A6: Course Title | C6: Principles of Banking
A7: Credit Value | C7: 3
A8: Lecturer | C8: Mme. Lukong Claris
A9: Level: 1
A10: S/N | B10: MAT. NO | C10: NAME | D10: Exam Codes | E10: Att/10 | F10: CA/30 | G10: Tot/40 | H10: sign in | I10: sign out | J10: Exam/60 | K10: Total/100 | L10: Grades | M10: Remarks
A12: =ROW(A1) -> 1 | B12: 381323H | C12: Abah Rameline Abo | D12: BFI1101H/6 | E12: 9 | F12: 21 | G12: =SUM(E12:F12) -> 30 | J12: 48 | K12: =SUM(G12:J12) -> 78 | L12: =IF(K12>=80,"A",IF(K12>=70,"B+",IF(K12>=60,"B",IF(K12>=55,"C+",IF(K12>=50,"C",IF(K12>=45,"D+",IF(K12>=40,"D","F"))))))) -> B+ | M12: =IF(K12>=50,"Passed","Failed") -> Passed | N12: STATISTICS
A13: =ROW(A2) -> 2 | B13: 378523H | C13: Abembom Kuate-mein Quinn Laurato | D13: BFI1101H/15 | E13: 10 | F13: 21 | G13: =SUM(E13:F13) -> 31 | J13: 43 | K13: =SUM(G13:J13) -> 74 | L13: =IF(K13>=80,"A",IF(K13>=70,"B+",IF(K13>=60,"B",IF(K13>=55,"C+",IF(K13>=50,"C",IF(K13>=45,"D+",IF(K13>=40,"D","F"))))))) -> B+ | M13: =IF(K13>=50,"Passed","Failed") -> Passed | N13: No. Registered | O13: =COUNT(G12:G65) -> 54
A14: =ROW(A3) -> 3 | B14: 377423H | C14: Awantang Mary-Lily | D14: BFI1101H/18 | E14: 10 | F14: 22 | G14: =SUM(E14:F14) -> 32 | J14: 42 | K14: =SUM(G14:J14) -> 74 | L14: =IF(K14>=80,"A",IF(K14>=70,"B+",IF(K14>=60,"B",IF(K14>=55,"C+",IF(K14>=50,"C",IF(K14>=45,"D+",IF(K14>=40,"D","F"))))))) -> B+ | M14: =IF(K14>=50,"Passed","Failed") -> Passed | N14: No. Examined | O14: =COUNT(J12:J65) -> 54
A15: =ROW(A4) -> 4 | B15: 378423H | C15: Azhinwie Jude Nde | D15: BFI1101H/27 | E15: 10 | F15: 22 | G15: =SUM(E15:F15) -> 32 | J15: 45 | K15: =SUM(G15:J15) -> 77 | L15: =IF(K15>=80,"A",IF(K15>=70,"B+",IF(K15>=60,"B",IF(K15>=55,"C+",IF(K15>=50,"C",IF(K15>=45,"D+",IF(K15>=40,"D","F"))))))) -> B+ | M15: =IF(K15>=50,"Passed","Failed") -> Passed | N15: No . ABS | O15: =O13-O14 -> 0
A16: =ROW(A5) -> 5 | B16: 383023H | C16: Bemsimbom consolata ndiwum | D16: BFI1101H/2 | E16: 10 | F16: 20 | G16: =SUM(E16:F16) -> 30 | J16: 57 | K16: =SUM(G16:J16) -> 87 | L16: =IF(K16>=80,"A",IF(K16>=70,"B+",IF(K16>=60,"B",IF(K16>=55,"C+",IF(K16>=50,"C",IF(K16>=45,"D+",IF(K16>=40,"D","F"))))))) -> A | M16: =IF(K16>=50,"Passed","Failed") -> Passed | N16: No. Passed | O16: =COUNTIF(M12:M65,"Passed") -> 47
A17: =ROW(A6) -> 6 | B17: 382323H | C17: Bih Noela | D17: BFI1101H/43 | E17: 10 | F17: 23 | G17: =SUM(E17:F17) -> 33 | J17: 50 | K17: =SUM(G17:J17) -> 83 | L17: =IF(K17>=80,"A",IF(K17>=70,"B+",IF(K17>=60,"B",IF(K17>=55,"C+",IF(K17>=50,"C",IF(K17>=45,"D+",IF(K17>=40,"D","F"))))))) -> A | M17: =IF(K17>=50,"Passed","Failed") -> Passed | N17: % Pass | O17: =O16/O14% -> 87.037037
A18: =ROW(A7) -> 7 | B18: 378223H | C18: Bobga Genevieve Nahlelah | D18: BFI1101H/42 | E18: 10 | F18: 12 | G18: =SUM(E18:F18) -> 22 | J18: 17 | K18: =SUM(G18:J18) -> 39 | L18: =IF(K18>=80,"A",IF(K18>=70,"B+",IF(K18>=60,"B",IF(K18>=55,"C+",IF(K18>=50,"C",IF(K18>=45,"D+",IF(K18>=40,"D","F"))))))) -> F | M18: =IF(K18>=50,"Passed","Failed") -> Failed | N18: No. Failed | O18: =COUNTIF(M12:M65,"failed") -> 7
A19: =ROW(A8) -> 8 | B19: 376823H | C19: Chendze Adel Akwanwi | D19: BFI1101H/38 | E19: 9 | F19: 23 | G19: =SUM(E19:F19) -> 32 | J19: 54 | K19: =SUM(G19:J19) -> 86 | L19: =IF(K19>=80,"A",IF(K19>=70,"B+",IF(K19>=60,"B",IF(K19>=55,"C+",IF(K19>=50,"C",IF(K19>=45,"D+",IF(K19>=40,"D","F"))))))) -> A | M19: =IF(K19>=50,"Passed","Failed") -> Passed | N19: % Failed | O19: =O18/O14% -> 12.962963
A20: =ROW(A9) -> 9 | B20: 382423H | C20: Chi Favor Nangah | D20: BFI1101H/47 | E20: 9 | F20: 23 | G20: =SUM(E20:F20) -> 32 | J20: 57 | K20: =SUM(G20:J20) -> 89 | L20: =IF(K20>=80,"A",IF(K20>=70,"B+",IF(K20>=60,"B",IF(K20>=55,"C+",IF(K20>=50,"C",IF(K20>=45,"D+",IF(K20>=40,"D","F"))))))) -> A | M20: =IF(K20>=50,"Passed","Failed") -> Passed | N20: Course Average | O20: =AVERAGE(K12:K65) -> 66.833333
A21: =ROW(A10) -> 10 | B21: 377523H | C21: Djouka Pouokam Dolie Stella | D21: BFI1101H/35 | E21: 9 | F21: 20 | G21: =SUM(E21:F21) -> 29 | J21: 17 | K21: =SUM(G21:J21) -> 46 | L21: =IF(K21>=80,"A",IF(K21>=70,"B+",IF(K21>=60,"B",IF(K21>=55,"C+",IF(K21>=50,"C",IF(K21>=45,"D+",IF(K21>=40,"D","F"))))))) -> D+ | M21: =IF(K21>=50,"Passed","Failed") -> Failed
A22: =ROW(A11) -> 11 | B22: 381623H | C22: Fonah Favour Ngongmene | D22: BFI1101H/32 | E22: 10 | F22: 24 | G22: =SUM(E22:F22) -> 34 | J22: 42 | K22: =SUM(G22:J22) -> 76 | L22: =IF(K22>=80,"A",IF(K22>=70,"B+",IF(K22>=60,"B",IF(K22>=55,"C+",IF(K22>=50,"C",IF(K22>=45,"D+",IF(K22>=40,"D","F"))))))) -> B+ | M22: =IF(K22>=50,"Passed","Failed") -> Passed
A23: =ROW(A12) -> 12 | B23: 380923H | C23: Forcham Emmanuel Forgwe | D23: BFI1101H/22 | E23: 9 | F23: 13 | G23: =SUM(E23:F23) -> 22 | J23: 28 | K23: =SUM(G23:J23) -> 50 | L23: =IF(K23>=80,"A",IF(K23>=70,"B+",IF(K23>=60,"B",IF(K23>=55,"C+",IF(K23>=50,"C",IF(K23>=45,"D+",IF(K23>=40,"D","F"))))))) -> C | M23: =IF(K23>=50,"Passed","Failed") -> Passed
A24: =ROW(A13) -> 13 | B24: 379423H | C24: Fonyuy Francesco Ngalle | D24: BFI1101H/3 | E24: 10 | F24: 17 | G24: =SUM(E24:F24) -> 27 | J24: 60 | K24: =SUM(G24:J24) -> 87 | L24: =IF(K24>=80,"A",IF(K24>=70,"B+",IF(K24>=60,"B",IF(K24>=55,"C+",IF(K24>=50,"C",IF(K24>=45,"D+",IF(K24>=40,"D","F"))))))) -> A | M24: =IF(K24>=50,"Passed","Failed") -> Passed | R24: A | S24: B+ | T24: B | U24: C+ | V24: C | W24: D+ | X24: D | Y24: F
A25: =ROW(A14) -> 14 | B25: 398623H | C25: Julinatu Fatu | D25: BFI1101H/50 | E25: 10 | F25: 23 | G25: =SUM(E25:F25) -> 33 | J25: 34 | K25: =SUM(G25:J25) -> 67 | L25: =IF(K25>=80,"A",IF(K25>=70,"B+",IF(K25>=60,"B",IF(K25>=55,"C+",IF(K25>=50,"C",IF(K25>=45,"D+",IF(K25>=40,"D","F"))))))) -> B | M25: =IF(K25>=50,"Passed","Failed") -> Passed | R25: =COUNTIF(L12:L65,"A") -> 12 | S25: =COUNTIF(L12:L65,"B+") -> 17 | T25: =COUNTIF(L12:L65,"B") -> 9 | U25: =COUNTIF(L12:L65,"C+") -> 4 | V25: =COUNTIF(L12:L65,"C") -> 5 | W25: =COUNTIF(L12:L65,"D+") -> 1 | X25: =COUNTIF(L12:L65,"D") -> 2 | Y25: =COUNTIF(L12:L65,"F") -> 4
A26: =ROW(A15) -> 15 | B26: 385123H | C26: Kelly Chelsea Eweh | D26: BFI1101H/11 | E26: 10 | F26: 15 | G26: =SUM(E26:F26) -> 25 | J26: 46 | K26: =SUM(G26:J26) -> 71 | L26: =IF(K26>=80,"A",IF(K26>=70,"B+",IF(K26>=60,"B",IF(K26>=55,"C+",IF(K26>=50,"C",IF(K26>=45,"D+",IF(K26>=40,"D","F"))))))) -> B+ | M26: =IF(K26>=50,"Passed","Failed") -> Passed
A27: =ROW(A16) -> 16 | B27: 381723H | C27: Kien Shella Tingoh | D27: BFI1101H/12 | E27: 8 | F27: 25 | G27: =SUM(E27:F27) -> 33 | J27: 48 | K27: =SUM(G27:J27) -> 81 | L27: =IF(K27>=80,"A",IF(K27>=70,"B+",IF(K27>=60,"B",IF(K27>=55,"C+",IF(K27>=50,"C",IF(K27>=45,"D+",IF(K27>=40,"D","F"))))))) -> A | M27: =IF(K27>=50,"Passed","Failed") -> Passed
A28: =ROW(A17) -> 17 | B28: 382823H | C28: Kwankep Mirielle Chunack | D28: BFI1101H/40 | E28: 9 | F28: 21 | G28: =SUM(E28:F28) -> 30 | J28: 38 | K28: =SUM(G28:J28) -> 68 | L28: =IF(K28>=80,"A",IF(K28>=70,"B+",IF(K28>=60,"B",IF(K28>=55,"C+",IF(K28>=50,"C",IF(K28>=45,"D+",IF(K28>=40,"D","F"))))))) -> B | M28: =IF(K28>=50,"Passed","Failed") -> Passed
A29: =ROW(A18) -> 18 | B29: 381123H | C29: Leonora Lemnwie Ndifor | D29: BFI1101H/30 | E29: 10 | F29: 16 | G29: =SUM(E29:F29) -> 26 | J29: 36 | K29: =SUM(G29:J29) -> 62 | L29: =IF(K29>=80,"A",IF(K29>=70,"B+",IF(K29>=60,"B",IF(K29>=55,"C+",IF(K29>=50,"C",IF(K29>=45,"D+",IF(K29>=40,"D","F"))))))) -> B | M29: =IF(K29>=50,"Passed","Failed") -> Passed
A30: =ROW(A19) -> 19 | B30: 389623H | C30: Lobga Wesley Nuvaga Tiwa | D30: BFI1101H/24 | E30: 10 | F30: 18 | G30: =SUM(E30:F30) -> 28 | J30: 54 | K30: =SUM(G30:J30) -> 82 | L30: =IF(K30>=80,"A",IF(K30>=70,"B+",IF(K30>=60,"B",IF(K30>=55,"C+",IF(K30>=50,"C",IF(K30>=45,"D+",IF(K30>=40,"D","F"))))))) -> A | M30: =IF(K30>=50,"Passed","Failed") -> Passed
A31: =ROW(A20) -> 20 | B31: 389023H | C31: Mankah Anna Nde | D31: BFI1101H/1 | E31: 9 | F31: 14 | G31: =SUM(E31:F31) -> 23 | J31: 28 | K31: =SUM(G31:J31) -> 51 | L31: =IF(K31>=80,"A",IF(K31>=70,"B+",IF(K31>=60,"B",IF(K31>=55,"C+",IF(K31>=50,"C",IF(K31>=45,"D+",IF(K31>=40,"D","F"))))))) -> C | M31: =IF(K31>=50,"Passed","Failed") -> Passed
A32: =ROW(A21) -> 21 | B32: 384823H | C32: Mbah Audrey Ngwe | D32: BFI1101H/34 | E32: 9 | F32: 15 | G32: =SUM(E32:F32) -> 24 | J32: 48 | K32: =SUM(G32:J32) -> 72 | L32: =IF(K32>=80,"A",IF(K32>=70,"B+",IF(K32>=60,"B",IF(K32>=55,"C+",IF(K32>=50,"C",IF(K32>=45,"D+",IF(K32>=40,"D","F"))))))) -> B+ | M32: =IF(K32>=50,"Passed","Failed") -> Passed
A33: =ROW(A22) -> 22 | B33: 404023H | C33: Ndamukong Jirez | D33: BFI1101H/13 | E33: 8 | F33: 19 | G33: =SUM(E33:F33) -> 27 | J33: 45 | K33: =SUM(G33:J33) -> 72 | L33: =IF(K33>=80,"A",IF(K33>=70,"B+",IF(K33>=60,"B",IF(K33>=55,"C+",IF(K33>=50,"C",IF(K33>=45,"D+",IF(K33>=40,"D","F"))))))) -> B+ | M33: =IF(K33>=50,"Passed","Failed") -> Passed
A34: =ROW(A23) -> 23 | B34: 387923H | C34: Ndipmun Cynthia Atuo | D34: BFI1101H/10 | E34: 8 | F34: 25 | G34: =SUM(E34:F34) -> 33 | J34: 43 | K34: =SUM(G34:J34) -> 76 | L34: =IF(K34>=80,"A",IF(K34>=70,"B+",IF(K34>=60,"B",IF(K34>=55,"C+",IF(K34>=50,"C",IF(K34>=45,"D+",IF(K34>=40,"D","F"))))))) -> B+ | M34: =IF(K34>=50,"Passed","Failed") -> Passed
A35: =ROW(A24) -> 24 | B35: 379023H | C35: Neiwoubua Chelsea Abubarka | D35: BFI1101H/16 | E35: 9 | F35: 19 | G35: =SUM(E35:F35) -> 28 | J35: 48 | K35: =SUM(G35:J35) -> 76 | L35: =IF(K35>=80,"A",IF(K35>=70,"B+",IF(K35>=60,"B",IF(K35>=55,"C+",IF(K35>=50,"C",IF(K35>=45,"D+",IF(K35>=40,"D","F"))))))) -> B+ | M35: =IF(K35>=50,"Passed","Failed") -> Passed
A36: =ROW(A25) -> 25 | B36: 380623H | C36: Ngwain Gisele Fuen | D36: BFI1101H/26 | E36: 10 | F36: 25 | G36: =SUM(E36:F36) -> 35 | J36: 17 | K36: =SUM(G36:J36) -> 52 | L36: =IF(K36>=80,"A",IF(K36>=70,"B+",IF(K36>=60,"B",IF(K36>=55,"C+",IF(K36>=50,"C",IF(K36>=45,"D+",IF(K36>=40,"D","F"))))))) -> C | M36: =IF(K36>=50,"Passed","Failed") -> Passed
A37: =ROW(A26) -> 26 | B37: 382723H | C37: Nji Dilian Chi | D37: BFI1101H/52 | E37: 9 | F37: 18 | G37: =SUM(E37:F37) -> 27 | J37: 34 | K37: =SUM(G37:J37) -> 61 | L37: =IF(K37>=80,"A",IF(K37>=70,"B+",IF(K37>=60,"B",IF(K37>=55,"C+",IF(K37>=50,"C",IF(K37>=45,"D+",IF(K37>=40,"D","F"))))))) -> B | M37: =IF(K37>=50,"Passed","Failed") -> Passed
A38: =ROW(A27) -> 27 | B38: 381423H | C38: Nkwelong Elizabeth Ebombe | D38: BFI1101H/33 | E38: 10 | F38: 19 | G38: =SUM(E38:F38) -> 29 | J38: 42 | K38: =SUM(G38:J38) -> 71 | L38: =IF(K38>=80,"A",IF(K38>=70,"B+",IF(K38>=60,"B",IF(K38>=55,"C+",IF(K38>=50,"C",IF(K38>=45,"D+",IF(K38>=40,"D","F"))))))) -> B+ | M38: =IF(K38>=50,"Passed","Failed") -> Passed
A39: =ROW(A28) -> 28 | B39: 400123 | C39: Tata Shella Ijang | D39: BFI1101H/36 | E39: 10 | F39: 7 | G39: =SUM(E39:F39) -> 17 | J39: 42 | K39: =SUM(G39:J39) -> 59 | L39: =IF(K39>=80,"A",IF(K39>=70,"B+",IF(K39>=60,"B",IF(K39>=55,"C+",IF(K39>=50,"C",IF(K39>=45,"D+",IF(K39>=40,"D","F"))))))) -> C+ | M39: =IF(K39>=50,"Passed","Failed") -> Passed
A40: =ROW(A29) -> 29 | B40: 378623H | C40: Keunang Tchouala Blaise | D40: BFI1101H/7 | E40: 10 | F40: 9 | G40: =SUM(E40:F40) -> 19 | J40: 44 | K40: =SUM(G40:J40) -> 63 | L40: =IF(K40>=80,"A",IF(K40>=70,"B+",IF(K40>=60,"B",IF(K40>=55,"C+",IF(K40>=50,"C",IF(K40>=45,"D+",IF(K40>=40,"D","F"))))))) -> B | M40: =IF(K40>=50,"Passed","Failed") -> Passed
A41: =ROW(A30) -> 30 | B41: 379223H | C41: Teko Desmourine Engonwei | D41: BFI1101H/9 | E41: 10 | F41: 21 | G41: =SUM(E41:F41) -> 31 | J41: 56 | K41: =SUM(G41:J41) -> 87 | L41: =IF(K41>=80,"A",IF(K41>=70,"B+",IF(K41>=60,"B",IF(K41>=55,"C+",IF(K41>=50,"C",IF(K41>=45,"D+",IF(K41>=40,"D","F"))))))) -> A | M41: =IF(K41>=50,"Passed","Failed") -> Passed
...

Sheet FBMS-HND LEVEL TWO
A1: Catholic University of Cameroon, CATUC, Bamenda
A2: Faculty of business & Management Sciences-HND
A3: First Semester Exam 2023-2024
A4: Department: | B4: Common course
A5: Course Code | B5: FRE 2101
A6: Course Title | B6: Functional French III
A7: Credit Value | B7: 2
A8: Lecturer | B8: Dr Ngoran George
A9: Level: 2 | B9: HND/FBMS 2 | L9: Grades | M9: Remarks | N9: STATISTICS
A10: S/N | B10: MAT. NO | C10: NAME | D10: Exam Codes | E10: Att/10 | F10: CA/30 | G10: Tot/40 | H10: sign in | I10: sign out | J10: Exam/60 | K10: Total/100 | N10: No. Registered | O10: =COUNT(G12:G65) -> 51
A11: Common Course | N11: No. Examined | O11: =COUNT(J12:J65) -> 48
A12: =ROW(A1) -> 1 | B12: 338222H | C12: Abdou Ziena Madinatou | D12: FRE 2101/17 | E12: 8 | F12: 23 | G12: =SUM(E12:F12) -> 31 | J12: 26 | K12: =SUM(G12:J12) -> 57 | L12: =IF(K12>=80,"A",IF(K12>=70,"B+",IF(K12>=60,"B",IF(K12>=55,"C+",IF(K12>=50,"C",IF(K12>=45,"D+",IF(K12>=40,"D","F"))))))) -> C+ | M12: =IF(K12>=50,"Passed","Failed") -> Passed | N12: No . ABS | O12: =O10-O11 -> 3
A13: =ROW(A2) -> 2 | B13: 330322H | C13: Acha Victory Nweyeh-kah | D13: FRE 2101/44 | E13: 8 | F13: 19 | G13: =SUM(E13:F13) -> 27 | J13: 26 | K13: =SUM(G13:J13) -> 53 | L13: =IF(K13>=80,"A",IF(K13>=70,"B+",IF(K13>=60,"B",IF(K13>=55,"C+",IF(K13>=50,"C",IF(K13>=45,"D+",IF(K13>=40,"D","F"))))))) -> C | M13: =IF(K13>=50,"Passed","Failed") -> Passed | N13: No. Passed | O13: =COUNTIF(M12:M65,"Passed") -> 37
A14: =ROW(A3) -> 3 | B14: 340822H | C14: Akang Courage Bi | D14: FRE 2101/12 | E14: 8 | F14: 23 | G14: =SUM(E14:F14) -> 31 | J14: 28 | K14: =SUM(G14:J14) -> 59 | L14: =IF(K14>=80,"A",IF(K14>=70,"B+",IF(K14>=60,"B",IF(K14>=55,"C+",IF(K14>=50,"C",IF(K14>=45,"D+",IF(K14>=40,"D","F"))))))) -> C+ | M14: =IF(K14>=50,"Passed","Failed") -> Passed | N14: % Pass | O14: =O13/O11% -> 77.083333
A15: =ROW(A4) -> 4 | B15: 340922H | C15: Awah Priddy Mboh-Ngeh | D15: FRE 2101/34 | E15: 8 | F15: 22 | G15: =SUM(E15:F15) -> 30 | J15: 20 | K15: =SUM(G15:J15) -> 50 | L15: =IF(K15>=80,"A",IF(K15>=70,"B+",IF(K15>=60,"B",IF(K15>=55,"C+",IF(K15>=50,"C",IF(K15>=45,"D+",IF(K15>=40,"D","F"))))))) -> C | M15: =IF(K15>=50,"Passed","Failed") -> Passed | N15: No. Failed | O15: =COUNTIF(M12:M65,"failed") -> 11
A16: =ROW(A5) -> 5 | B16: 330522H | C16: Bin Abigael Nwa | D16: FRE 2101/21 | E16: 8 | F16: 26 | G16: =SUM(E16:F16) -> 34 | J16: 32 | K16: =SUM(G16:J16) -> 66 | L16: =IF(K16>=80,"A",IF(K16>=70,"B+",IF(K16>=60,"B",IF(K16>=55,"C+",IF(K16>=50,"C",IF(K16>=45,"D+",IF(K16>=40,"D","F"))))))) -> B | M16: =IF(K16>=50,"Passed","Failed") -> Passed | N16: % Failed | O16: =O15/O11% -> 22.916667
A17: =ROW(A6) -> 6 | B17: 337322H | C17: Famah Shamah Nfor | D17: FRE 2101/11 | E17: 8 | F17: 21 | G17: =SUM(E17:F17) -> 29 | J17: 26 | K17: =SUM(G17:J17) -> 55 | L17: =IF(K17>=80,"A",IF(K17>=70,"B+",IF(K17>=60,"B",IF(K17>=55,"C+",IF(K17>=50,"C",IF(K17>=45,"D+",IF(K17>=40,"D","F"))))))) -> C+ | M17: =IF(K17>=50,"Passed","Failed") -> Passed | N17: Course Average | O17: =AVERAGE(K12:K65) -> 52.541667
A18: =ROW(A7) -> 7 | B18: 360022H | C18: Favour Bongnavti Aloni | D18: FRE 2101/
A19: =ROW(A8) -> 8 | B19: 345122H | C19: Fri Jenifer Chick | D19: FRE 2101/32 | E19: 8 | F19: 22 | G19: =SUM(E19:F19) -> 30 | J19: 24 | K19: =SUM(G19:J19) -> 54 | L19: =IF(K19>=80,"A",IF(K19>=70,"B+",IF(K19>=60,"B",IF(K19>=55,"C+",IF(K19>=50,"C",IF(K19>=45,"D+",IF(K19>=40,"D","F"))))))) -> C | M19: =IF(K19>=50,"Passed","Failed") -> Passed
A20: =ROW(A9) -> 9 | B20: 329522H | C20: Hawa Amira Ibrahim | D20: FRE 2101/37 | E20: 8 | F20: 21 | G20: =SUM(E20:F20) -> 29 | J20: 42 | K20: =SUM(G20:J20) -> 71 | L20: =IF(K20>=80,"A",IF(K20>=70,"B+",IF(K20>=60,"B",IF(K20>=55,"C+",IF(K20>=50,"C",IF(K20>=45,"D+",IF(K20>=40,"D","F"))))))) -> B+ | M20: =IF(K20>=50,"Passed","Failed") -> Passed | N20: Grades
A21: =ROW(A10) -> 10 | B21: 352522H | C21: Mbuya Excel Ngeh | D21: FRE 2101/15 | E21: 8 | F21: 12 | G21: =SUM(E21:F21) -> 20 | J21: 8 | K21: =SUM(G21:J21) -> 28 | L21: =IF(K21>=80,"A",IF(K21>=70,"B+",IF(K21>=60,"B",IF(K21>=55,"C+",IF(K21>=50,"C",IF(K21>=45,"D+",IF(K21>=40,"D","F"))))))) -> F | M21: =IF(K21>=50,"Passed","Failed") -> Failed | O21: A | P21: B+ | Q21: B | R21: C+ | S21: C | T21: D+ | U21: D | V21: F
A22: =ROW(A11) -> 11 | B22: 320021H | C22: Muna Beltus | D22: FRE 2101/ | O22: =COUNTIF(L12:L65,"A") -> 0 | P22: =COUNTIF(L12:L65,"B+") -> 2 | Q22: =COUNTIF(L12:L65,"B") -> 9 | R22: =COUNTIF(L12:L65,"C+") -> 9 | S22: =COUNTIF(L12:L65,"C") -> 17 | T22: =COUNTIF(L12:L65,"D+") -> 2 | U22: =COUNTIF(L12:L65,"D") -> 5 | V22: =COUNTIF(L12:L65,"F") -> 4
A23: =ROW(A12) -> 12 | B23: 330422H | C23: Nde Cindy-Bright Luh | D23: FRE 2101/3 | E23: 8 | F23: 19 | G23: =SUM(E23:F23) -> 27 | J23: 31 | K23: =SUM(G23:J23) -> 58 | L23: =IF(K23>=80,"A",IF(K23>=70,"B+",IF(K23>=60,"B",IF(K23>=55,"C+",IF(K23>=50,"C",IF(K23>=45,"D+",IF(K23>=40,"D","F"))))))) -> C+ | M23: =IF(K23>=50,"Passed","Failed") -> Passed
A24: =ROW(A13) -> 13 | B24: 337922H | C24: Ndukong Seraphine Mangwang | D24: FRE 2101/8 | E24: 8 | F24: 15 | G24: =SUM(E24:F24) -> 23 | J24: 31 | K24: =SUM(G24:J24) -> 54 | L24: =IF(K24>=80,"A",IF(K24>=70,"B+",IF(K24>=60,"B",IF(K24>=55,"C+",IF(K24>=50,"C",IF(K24>=45,"D+",IF(K24>=40,"D","F"))))))) -> C | M24: =IF(K24>=50,"Passed","Failed") -> Passed
A25: 14 | B25: 341722H | C25: Nformi Christabella | D25: FRE 2101/46 | E25: 8 | F25: 15 | G25: =SUM(E25:F25) -> 23 | J25: 19 | K25: =SUM(G25:J25) -> 42 | L25: =IF(K25>=80,"A",IF(K25>=70,"B+",IF(K25>=60,"B",IF(K25>=55,"C+",IF(K25>=50,"C",IF(K25>=45,"D+",IF(K25>=40,"D","F"))))))) -> D | M25: =IF(K25>=50,"Passed","Failed") -> Failed
A26: =ROW(A15) -> 15 | B26: 347622H | C26: Ngam Hedwig Afumbom | D26: FRE 2101/47 | E26: 8 | F26: 21 | G26: =SUM(E26:F26) -> 29 | J26: 21 | K26: =SUM(G26:J26) -> 50 | L26: =IF(K26>=80,"A",IF(K26>=70,"B+",IF(K26>=60,"B",IF(K26>=55,"C+",IF(K26>=50,"C",IF(K26>=45,"D+",IF(K26>=40,"D","F"))))))) -> C | M26: =IF(K26>=50,"Passed","Failed") -> Passed
A27: =ROW(A16) -> 16 | B27: 329422H | C27: Ngwa Joseph Neba | D27: FRE 2101/20 | E27: 8 | F27: 18 | G27: =SUM(E27:F27) -> 26 | J27: 14 | K27: =SUM(G27:J27) -> 40 | L27: =IF(K27>=80,"A",IF(K27>=70,"B+",IF(K27>=60,"B",IF(K27>=55,"C+",IF(K27>=50,"C",IF(K27>=45,"D+",IF(K27>=40,"D","F"))))))) -> D | M27: =IF(K27>=50,"Passed","Failed") -> Failed
A28: =ROW(A17) -> 17 | B28: 350122H | C28: Nyuydzewira Lorantine Shuka | D28: FRE 2101/16 | E28: 8 | F28: 21 | G28: =SUM(E28:F28) -> 29 | J28: 32 | K28: =SUM(G28:J28) -> 61 | L28: =IF(K28>=80,"A",IF(K28>=70,"B+",IF(K28>=60,"B",IF(K28>=55,"C+",IF(K28>=50,"C",IF(K28>=45,"D+",IF(K28>=40,"D","F"))))))) -> B | M28: =IF(K28>=50,"Passed","Failed") -> Passed
A29: =ROW(A18) -> 18 | B29: 367522H | C29: Samnissi Rawllings Galabe | D29: FRE 2101/2 | G29: =SUM(E29:F29) -> 0 | J29: 11 | K29: =SUM(G29:J29) -> 11 | L29: =IF(K29>=80,"A",IF(K29>=70,"B+",IF(K29>=60,"B",IF(K29>=55,"C+",IF(K29>=50,"C",IF(K29>=45,"D+",IF(K29>=40,"D","F"))))))) -> F | M29: =IF(K29>=50,"Passed","Failed") -> Failed
A30: =ROW(A19) -> 19 | B30: 335622H | C30: Stercy Megan Agbor | D30: FRE 2101/26 | G30: =SUM(E30:F30) -> 0 | J30: 33 | K30: =SUM(G30:J30) -> 33 | L30: =IF(K30>=80,"A",IF(K30>=70,"B+",IF(K30>=60,"B",IF(K30>=55,"C+",IF(K30>=50,"C",IF(K30>=45,"D+",IF(K30>=40,"D","F"))))))) -> F | M30: =IF(K30>=50,"Passed","Failed") -> Failed
A31: =ROW(A20) -> 20 | B31: 347022H | C31: Suzyl Wiyrdzernyuy | D31: FRE 2101/36 | E31: 8 | F31: 30 | G31: =SUM(E31:F31) -> 38 | J31: 27 | K31: =SUM(G31:J31) -> 65 | L31: =IF(K31>=80,"A",IF(K31>=70,"B+",IF(K31>=60,"B",IF(K31>=55,"C+",IF(K31>=50,"C",IF(K31>=45,"D+",IF(K31>=40,"D","F"))))))) -> B | M31: =IF(K31>=50,"Passed","Failed") -> Passed
A32: =ROW(A21) -> 21 | B32: 337222H | C32: Tah Marceline Kemaka | D32: FRE 2101/9 | E32: 8 | F32: 18 | G32: =SUM(E32:F32) -> 26 | J32: 27 | K32: =SUM(G32:J32) -> 53 | L32: =IF(K32>=80,"A",IF(K32>=70,"B+",IF(K32>=60,"B",IF(K32>=55,"C+",IF(K32>=50,"C",IF(K32>=45,"D+",IF(K32>=40,"D","F"))))))) -> C | M32: =IF(K32>=50,"Passed","Failed") -> Passed
A33: =ROW(A22) -> 22 | B33: 344522H | C33: Yirenwie-Mado Favour Munjere | D33: FRE 2101/14 | E33: 8 | F33: 19 | G33: =SUM(E33:F33) -> 27 | J33: 33 | K33: =SUM(G33:J33) -> 60 | L33: =IF(K33>=80,"A",IF(K33>=70,"B+",IF(K33>=60,"B",IF(K33>=55,"C+",IF(K33>=50,"C",IF(K33>=45,"D+",IF(K33>=40,"D","F"))))))) -> B | M33: =IF(K33>=50,"Passed","Failed") -> Passed
A34: =ROW(A23) -> 23 | B34: 334522H | C34: Ntungwen Brian | D34: FRE 2101/31 | E34: 8 | F34: 18 | G34: =SUM(E34:F34) -> 26 | J34: 26 | K34: =SUM(G34:J34) -> 52 | L34: =IF(K34>=80,"A",IF(K34>=70,"B+",IF(K34>=60,"B",IF(K34>=55,"C+",IF(K34>=50,"C",IF(K34>=45,"D+",IF(K34>=40,"D","F"))))))) -> C | M34: =IF(K34>=50,"Passed","Failed") -> Passed
A35: =ROW(A24) -> 24 | B35: 341822H | C35: Ajeakwa Keziah Umenek | D35: FRE 2101/22 | E35: 8 | F35: 16 | G35: =SUM(E35:F35) -> 24 | J35: 16 | K35: =SUM(G35:J35) -> 40 | L35: =IF(K35>=80,"A",IF(K35>=70,"B+",IF(K35>=60,"B",IF(K35>=55,"C+",IF(K35>=50,"C",IF(K35>=45,"D+",IF(K35>=40,"D","F"))))))) -> D | M35: =IF(K35>=50,"Passed","Failed") -> Failed
A36: =ROW(A25) -> 25 | B36: 335722H | C36: Bih Larissa Ngang | D36: FRE 2101/48 | E36: 8 | F36: 20 | G36: =SUM(E36:F36) -> 28 | J36: 34 | K36: =SUM(G36:J36) -> 62 | L36: =IF(K36>=80,"A",IF(K36>=70,"B+",IF(K36>=60,"B",IF(K36>=55,"C+",IF(K36>=50,"C",IF(K36>=45,"D+",IF(K36>=40,"D","F"))))))) -> B | M36: =IF(K36>=50,"Passed","Failed") -> Passed
A37: =ROW(A26) -> 26 | B37: 341522H | C37: Bih Mary-Ann Anchimbom Lainsi | D37: FRE 2101/10 | E37: 8 | F37: 22 | G37: =SUM(E37:F37) -> 30 | J37: 28 | K37: =SUM(G37:J37) -> 58 | L37: =IF(K37>=80,"A",IF(K37>=70,"B+",IF(K37>=60,"B",IF(K37>=55,"C+",IF(K37>=50,"C",IF(K37>=45,"D+",IF(K37>=40,"D","F"))))))) -> C+ | M37: =IF(K37>=50,"Passed","Failed") -> Passed
A38: =ROW(A27) -> 27 | B38: 328522H | C38: Formari Marion Mah | D38: FRE 2101/13 | E38: 8 | F38: 28 | G38: =SUM(E38:F38) -> 36 | J38: 14 | K38: =SUM(G38:J38) -> 50 | L38: =IF(K38>=80,"A",IF(K38>=70,"B+",IF(K38>=60,"B",IF(K38>=55,"C+",IF(K38>=50,"C",IF(K38>=45,"D+",IF(K38>=40,"D","F"))))))) -> C | M38: =IF(K38>=50,"Passed","Failed") -> Passed
A39: =ROW(A28) -> 28 | B39: 341022H | C39: Frou Excel Esepene | D39: FRE 2101/29 | E39: 8 | F39: 18 | G39: =SUM(E39:F39) -> 26 | J39: 24 | K39: =SUM(G39:J39) -> 50 | L39: =IF(K39>=80,"A",IF(K39>=70,"B+",IF(K39>=60,"B",IF(K39>=55,"C+",IF(K39>=50,"C",IF(K39>=45,"D+",IF(K39>=40,"D","F"))))))) -> C | M39: =IF(K39>=50,"Passed","Failed") -> Passed
A40: =ROW(A29) -> 29 | B40: 332422H | C40: Kemeng Marigiselle Nteinmussi | D40: FRE 2101/18 | E40: 8 | F40: 21 | G40: =SUM(E40:F40) -> 29 | J40: 35 | K40: =SUM(G40:J40) -> 64 | L40: =IF(K40>=80,"A",IF(K40>=70,"B+",IF(K40>=60,"B",IF(K40>=55,"C+",IF(K40>=50,"C",IF(K40>=45,"D+",IF(K40>=40,"D","F"))))))) -> B | M40: =IF(K40>=50,"Passed","Failed") -> Passed
...

Sheet Sheet1
C1: CATHOLIC UNIVERSITY OF CAMEROON (CATUC), BAMENDA
A3: SCHOOL/ FACULTY: FACULTY OF SCIENCE | C3: BUSINESS AND MANAGEMENT SCIENCES | L3: COMMON COURSES
L4: SEMESTER: FIRST SEMESTER
A5: HND | L5: SCHOOL YEAR: 2023/2024
C7: FREQUENCY DISTRIBUTION PERFORMANCES OF STUDENTS
A8: SN | B8: COURSE CODE | C8: COURSE TITLE | D8: CV | E8: ST | F8: LECTURERS | G8: % CC | H8: NUMBER | L8: % PASS | M8: % FAIL | N8: NUMBER
H9: CR | I9: CE | J9: PASS | K9: FAIL | N9: A | O9: B+ | P9: B | Q9: C+ | R9: C | S9: D+ | T9: D | U9: F
A10: 1 | B10: ='[1]level one'!$C$94 -> INS1101H | C10: ='[1]level one'!$C$95 -> Principles of Insurance | D10: ='[1]level one'!$C$96 -> 3 | E10: C | F10: Mme. Lukong Claris | H10: ='FBMS-HND LEVEL ONE'!$O$163 -> 54 | I10: ='FBMS-HND LEVEL ONE'!$O$164 -> 54 | J10: ='FBMS-HND LEVEL ONE'!$O$166 -> 40 | K10: ='FBMS-HND LEVEL ONE'!$O$168 -> 14 | L10: ='FBMS-HND LEVEL ONE'!$O$167 -> 74.074074 | M10: =K10/I10*100 -> 25.925926 | N10: ='FBMS-HND LEVEL ONE'!O175 -> 1 | O10: ='FBMS-HND LEVEL ONE'!P175 -> 6 | P10: ='FBMS-HND LEVEL ONE'!Q175 -> 14 | Q10: ='FBMS-HND LEVEL ONE'!R175 -> 6 | R10: ='FBMS-HND LEVEL ONE'!S175 -> 13 | S10: ='FBMS-HND LEVEL ONE'!T175 -> 3 | T10: ='FBMS-HND LEVEL ONE'!U175 -> 3 | U10: ='FBMS-HND LEVEL ONE'!V175 -> 8 | V10: =SUM(N10:U10) -> 54
A11: 2 | B11: ='[1]level one'!$C$296 -> ENG1101H | C11: ='[1]level one'!$C$297 -> Functional English I | D11: ='[1]level one'!$C$298 -> 2 | E11: C | F11: ='[1]level one'!$C$299 -> Dr Ngie Florence | H11: 150 | I11: 145 | J11: 144 | K11: 1 | L11: =J11/I11*100 -> 99.310345 | M11: =K11/I11*100 -> 0.68965517 | N11: 3 | O11: 50 | P11: 60 | Q11: 20 | R11: 11 | S11: 1 | T11: 0 | U11: 0 | V11: =SUM(N11:U11) -> 145
A12: 3 | B12: ='[1]level one'!$C$511 -> FRE1101H | C12: ='[1]level one'!$C$512 -> Functional French I | D12: ='[1]level one'!$C$513 -> 2 | E12: C | F12: Dr.Ngoran George | H12: ='FBMS-HND LEVEL ONE'!$O$745 -> 54 | I12: ='FBMS-HND LEVEL ONE'!$O$746 -> 54 | J12: ='FBMS-HND LEVEL ONE'!$O$748 -> 40 | K12: ='FBMS-HND LEVEL ONE'!$O$750 -> 14 | L12: =J12/I12*100 -> 74.074074 | M12: =K12/I12*100 -> 25.925926 | N12: ='FBMS-HND LEVEL ONE'!O758 -> 0 | O12: ='FBMS-HND LEVEL ONE'!P758 -> 9 | P12: ='FBMS-HND LEVEL ONE'!Q758 -> 22 | Q12: ='FBMS-HND LEVEL ONE'!R758 -> 2 | R12: ='FBMS-HND LEVEL ONE'!S758 -> 7 | S12: ='FBMS-HND LEVEL ONE'!T758 -> 3 | T12: ='FBMS-HND LEVEL ONE'!U758 -> 5 | U12: ='FBMS-HND LEVEL ONE'!V758 -> 6 | V12: =SUM(N12:U12) -> 54
A13: 4 | B13: ='[1]level two'!$C$4 -> FRE 2101H | C13: ='[1]level two'!$C$5 -> Functional French III | D13: ='[1]level two'!$C$6 -> 2 | E13: C | F13: Dr.Ngoran George | H13: ='FBMS-HND LEVEL TWO'!$O$10 -> 51 | I13: ='FBMS-HND LEVEL TWO'!$O$11 -> 48 | J13: ='FBMS-HND LEVEL TWO'!$O$13 -> 37 | K13: ='FBMS-HND LEVEL TWO'!$O$15 -> 11 | L13: =J13/I13*100 -> 77.083333 | M13: =K13/I13*100 -> 22.916667 | N13: ='FBMS-HND LEVEL TWO'!O22 -> 0 | O13: ='FBMS-HND LEVEL TWO'!P22 -> 2 | P13: ='FBMS-HND LEVEL TWO'!Q22 -> 9 | Q13: ='FBMS-HND LEVEL TWO'!R22 -> 9 | R13: ='FBMS-HND LEVEL TWO'!S22 -> 17 | S13: ='FBMS-HND LEVEL TWO'!T22 -> 2 | T13: ='FBMS-HND LEVEL TWO'!U22 -> 5 | U13: ='FBMS-HND LEVEL TWO'!V22 -> 4 | V13: =SUM(N13:U13) -> 48
A14: 5 | B14: ='[1]level two'!$C$36 -> ENG 2101H | C14: ='[1]level two'!$C$37 -> Functional English III | D14: ='[1]level two'!$C$38 -> 2 | E14: C | F14: ='[1]level two'!$C$39 -> Dr. Ngie Florence | H14: ='FBMS-HND LEVEL TWO'!$O$79 -> 50 | I14: ='FBMS-HND LEVEL TWO'!$O$80 -> 48 | J14: ='FBMS-HND LEVEL TWO'!$O$82 -> 46 | K14: ='FBMS-HND LEVEL TWO'!$O$84 -> 2 | L14: =J14/I14*100 -> 95.833333 | M14: =K14/I14*100 -> 4.1666667 | N14: ='FBMS-HND LEVEL TWO'!O91 -> 7 | O14: ='FBMS-HND LEVEL TWO'!P91 -> 13 | P14: ='FBMS-HND LEVEL TWO'!Q91 -> 19 | Q14: ='FBMS-HND LEVEL TWO'!R91 -> 5 | R14: ='FBMS-HND LEVEL TWO'!S91 -> 2 | S14: ='FBMS-HND LEVEL TWO'!T91 -> 1 | T14: ='FBMS-HND LEVEL TWO'!U91 -> 1 | U14: ='FBMS-HND LEVEL TWO'!V91 -> 0 | V14: =SUM(N14:U14) -> 48
A15: 6 | B15: ='[1]level two'!$C$141 -> COM 2101H | C15: ='[1]level two'!$C$142 -> Computer Science | D15: ='[1]level two'!$C$143 -> 2 | E15: C | F15: ='FBMS-HND LEVEL TWO'!$B$291 -> Mr.Nkeng Blaise | H15: ='FBMS-HND LEVEL TWO'!$O$295 -> 50 | I15: ='FBMS-HND LEVEL TWO'!$O$296 -> 49 | J15: ='FBMS-HND LEVEL TWO'!$O$298 -> 42 | K15: ='FBMS-HND LEVEL TWO'!$O$300 -> 7 | L15: =J15/I15*100 -> 85.714286 | M15: =K15/I15*100 -> 14.285714 | N15: ='FBMS-HND LEVEL TWO'!O307 -> 2 | O15: ='FBMS-HND LEVEL TWO'!P307 -> 5 | P15: ='FBMS-HND LEVEL TWO'!Q307 -> 16 | Q15: ='FBMS-HND LEVEL TWO'!R307 -> 9 | R15: ='FBMS-HND LEVEL TWO'!S307 -> 10 | S15: ='FBMS-HND LEVEL TWO'!T307 -> 2 | T15: ='FBMS-HND LEVEL TWO'!U307 -> 0 | U15: ='FBMS-HND LEVEL TWO'!V307 -> 5 | V15: =SUM(N15:U15) -> 49
B16: MGT 2207H | C16: Enterprise Creation and Entrepreneurship | D16: 3 | E16: C | F16: Dr. Wirsy Leonard | H16: ='FBMS-HND LEVEL TWO'!$O$574 -> 49 | I16: ='FBMS-HND LEVEL TWO'!$O$575 -> 49 | J16: ='FBMS-HND LEVEL TWO'!$O$577 -> 45 | K16: ='FBMS-HND LEVEL TWO'!$O$579 -> 4 | L16: =J16/I16*100 -> 91.836735 | M16: =K16/I16*100 -> 8.1632653 | N16: ='FBMS-HND LEVEL TWO'!$O$584 -> 0 | O16: ='FBMS-HND LEVEL TWO'!$O$585 -> A | P16: ='FBMS-HND LEVEL TWO'!$O$586 -> 20 | Q16: ='FBMS-HND LEVEL TWO'!$O$587 -> 0 | R16: ='FBMS-HND LEVEL TWO'!$O$588 -> 0 | S16: ='FBMS-HND LEVEL TWO'!$O$589 -> 0 | T16: ='FBMS-HND LEVEL TWO'!$O$590 -> 0 | U16: ='FBMS-HND LEVEL TWO'!$O$591 -> 0
C17: TOTAL/ AVERAGE | H17: =SUM(H10:H15) -> 409 | I17: =SUM(I10:I15) -> 398 | J17: =SUM(J10:J15) -> 349 | K17: =SUM(K10:K15) -> 49 | L17: =J17/I17*100 -> 87.688442 | M17: =K17/I17*100 -> 12.311558 | N17: =SUM(N10:N15) -> 13 | O17: =SUM(O10:O15) -> 85 | P17: =SUM(P10:P15) -> 140 | Q17: =SUM(Q10:Q15) -> 51 | R17: =SUM(R10:R15) -> 60 | S17: =SUM(S10:S15) -> 12 | T17: =SUM(T10:T15) -> 14 | U17: =SUM(U10:U15) -> 23 | V17: =SUM(N17:U17) -> 398
B18: CV = Credit Value; ST = Status (C = Compulsory; E = Elective); CR = Candidates Registered; CE = Candidates Examined; % CC = Course Coverage; The % Pass is based on CE (Candidates who completed the course by writing the final examination.
B20: Number of Marked Scripts: | D20: =$I$17 -> 398 | I20: Number of Failed Scripts | N20: =$K$17 -> 49
B22: Number of Passed Scripts | D22: =$J$17 -> 349
I23: Success Rate | M23: =$L$17 -> 87.688442
A24: Lecturers:
C26: =$F$10 -> Mme. Lukong Claris | F26: =$F$12 -> Dr.Ngoran George | K26: =$F$11 -> Dr Ngie Florence | P26: =$F$15 -> Mr.Nkeng Blaise
C30: Sr. Elizabeth Ankiambom | E30: Dr. | F30: Achiri Mongo Eric
C31: HND Cordinator | F31: Dean-FBMS-HND
C44: CATHOLIC UNIVERSITY OF CAMEROON (CATUC), BAMENDA
A46: SCHOOL/ FACULTY: FACULTY OF SCIENCE | C46: BUSINESS AND MANAGEMENT SCIENCES | L46: DEPARTMENT: ACCOUNTING
L47: SEMESTER: FIRST SEMESTER
A48: HND | L48: SCHOOL YEAR: 2023/2024
C50: FREQUENCY DISTRIBUTION PERFORMANCES OF STUDENTS
A51: SN | B51: COURSE CODE | C51: COURSE TITLE | D51: CV | E51: ST | F51: LECTURERS | G51: % CC | H51: NUMBER | L51: % PASS | M51: % FAIL | N51: NUMBER
H52: CR | I52: CE | J52: PASS | K52: FAIL | N52: A | O52: B+ | P52: B | Q52: C+ | R52: C | S52: D+ | T52: D | U52: F
A53: 1 | B53: ='[1]level one'!$C$402 -> ACC1102H | C53: ='[1]level one'!$C$403 -> OHADA Financial Accounting I | D53: 3 | E53: C | F53: Mr.Ngondo Charles | H53: ='FBMS-HND LEVEL ONE'!$O$599 -> 54 | I53: ='FBMS-HND LEVEL ONE'!$O$600 -> 54 | J53: ='FBMS-HND LEVEL ONE'!$O$602 -> 50 | K53: ='FBMS-HND LEVEL ONE'!$O$604 -> 4 | L53: =J53/I53*100 -> 92.592593 | M53: =K53/I53*100 -> 7.4074074 | N53: ='FBMS-HND LEVEL ONE'!O612 -> 3 | O53: ='FBMS-HND LEVEL ONE'!P612 -> 12 | P53: ='FBMS-HND LEVEL ONE'!Q612 -> 23 | Q53: ='FBMS-HND LEVEL ONE'!R612 -> 5 | R53: ='FBMS-HND LEVEL ONE'!S612 -> 7 | S53: ='FBMS-HND LEVEL ONE'!T612 -> 1 | T53: ='FBMS-HND LEVEL ONE'!U612 -> 2 | U53: ='FBMS-HND LEVEL ONE'!V612 -> 1 | V53: =SUM(N53:U53) -> 54
A54: 2 | B54: ACC1105H | C54: ='[1]level one'!$C$458 -> Principles of Taxation | D54: ='[1]level one'!$C$459 -> 3 | E54: C | F54: ='[1]level one'!$C$460 -> Mr Youopouo Maurice | H54: ='FBMS-HND LEVEL ONE'!$O$670 -> 54 | I54: ='FBMS-HND LEVEL ONE'!$O$671 -> 54 | J54: ='FBMS-HND LEVEL ONE'!$O$673 -> 39 | K54: ='FBMS-HND LEVEL ONE'!$O$675 -> 15 | L54: =J54/I54*100 -> 72.222222 | M54: =K54/I54*100 -> 27.777778 | N54: ='FBMS-HND LEVEL ONE'!O682 -> 3 | O54: ='FBMS-HND LEVEL ONE'!P682 -> 9 | P54: ='FBMS-HND LEVEL ONE'!Q682 -> 12 | Q54: ='FBMS-HND LEVEL ONE'!R682 -> 8 | R54: ='FBMS-HND LEVEL ONE'!S682 -> 7 | S54: ='FBMS-HND LEVEL ONE'!T682 -> 0 | T54: ='FBMS-HND LEVEL ONE'!U682 -> 1 | U54: ='FBMS-HND LEVEL ONE'!V682 -> 14 | V54: =SUM(N54:U54) -> 54
A55: 3 | B55: ='[1]level one'!$C$563 -> ACC1101H | C55: ='[1]level one'!$C$564 -> Principles of Accounting | D55: ='[1]level one'!$C$565 -> 3 | E55: C | F55: Mr Nzebir chrysantus | H55: ='FBMS-HND LEVEL ONE'!$O$813 -> 56 | I55: ='FBMS-HND LEVEL ONE'!$O$814 -> 55 | J55: ='FBMS-HND LEVEL ONE'!$O$816 -> 41 | K55: ='FBMS-HND LEVEL ONE'!$O$818 -> 14 | L55: =J55/I55*100 -> 74.545455 | M55: =K55/I55*100 -> 25.454545 | N55: ='FBMS-HND LEVEL ONE'!O826 -> 9 | O55: ='FBMS-HND LEVEL ONE'!P826 -> 14 | P55: ='FBMS-HND LEVEL ONE'!Q826 -> 7 | Q55: ='FBMS-HND LEVEL ONE'!R826 -> 4 | R55: ='FBMS-HND LEVEL ONE'!S826 -> 7 | S55: ='FBMS-HND LEVEL ONE'!T826 -> 2 | T55: ='FBMS-HND LEVEL ONE'!U826 -> 3 | U55: ='FBMS-HND LEVEL ONE'!V826 -> 9 | V55: =SUM(N55:U55) -> 55
A56: 4 | B56: ='[1]level two'!$C$104 -> ACC 2103H | C56: ='[1]level two'!$C$105 -> Cost & Management Accounting II | D56: ='[1]level two'!$C$106 -> 3 | E56: C | F56: Mr.Shiyghan Chrysanctus | H56: ='FBMS-HND LEVEL TWO'!$O$221 -> 50 | I56: ='FBMS-HND LEVEL TWO'!$O$222 -> 49 | J56: ='FBMS-HND LEVEL TWO'!$O$224 -> 39 | K56: ='FBMS-HND LEVEL TWO'!$O$226 -> 10 | L56: =J56/I56*100 -> 79.591837 | M56: =K56/I56*100 -> 20.408163 | N56: ='FBMS-HND LEVEL TWO'!O233 -> 9 | O56: ='FBMS-HND LEVEL TWO'!P233 -> 4 | P56: ='FBMS-HND LEVEL TWO'!Q233 -> 19 | Q56: ='FBMS-HND LEVEL TWO'!R233 -> 2 | R56: ='FBMS-HND LEVEL TWO'!S233 -> 5 | S56: ='FBMS-HND LEVEL TWO'!T233 -> 2 | T56: ='FBMS-HND LEVEL TWO'!U233 -> 4 | U56: ='FBMS-HND LEVEL TWO'!V233 -> 4 | V56: =SUM(N56:U56) -> 49
A57: 5 | B57: ='[1]level two'!$C$174 -> ACC 2105H | C57: ='[1]level two'!$C$175 -> Taxation I & II | D57: ='[1]level two'!$C$176 -> 3 | E57: C | F57: ='[1]level two'!$C$177 -> Mr. Youopouo Maurice | H57: ='FBMS-HND LEVEL TWO'!$O$370 -> 29 | I57: ='FBMS-HND LEVEL TWO'!$O$371 -> 29 | J57: ='FBMS-HND LEVEL TWO'!$O$373 -> 25 | K57: ='FBMS-HND LEVEL TWO'!$O$375 -> 4 | L57: =J57/I57*100 -> 86.206897 | M57: =K57/I57*100 -> 13.793103 | N57: ='FBMS-HND LEVEL TWO'!O382 -> 5 | O57: ='FBMS-HND LEVEL TWO'!P382 -> 2 | P57: ='FBMS-HND LEVEL TWO'!Q382 -> 8 | Q57: ='FBMS-HND LEVEL TWO'!R382 -> 4 | R57: ='FBMS-HND LEVEL TWO'!S382 -> 6 | S57: ='FBMS-HND LEVEL TWO'!T382 -> 0 | T57: ='FBMS-HND LEVEL TWO'!U382 -> 2 | U57: ='FBMS-HND LEVEL TWO'!V382 -> 2 | V57: =SUM(N57:U57) -> 29
A58: 6 | B58: ='[1]level two'!$C$332 -> ACC 2102H | C58: ='[1]level two'!$C$333 -> OHADA Financial Accounting III | D58: ='[1]level two'!$C$334 -> 3 | E58: C | F58: ='[1]level two'!$C$335 -> Mr. Youopouo Maurice | H58: ='FBMS-HND LEVEL TWO'!$O$699 -> 29 | I58: ='FBMS-HND LEVEL TWO'!$O$700 -> 28 | J58: ='FBMS-HND LEVEL TWO'!$O$702 -> 22 | K58: ='FBMS-HND LEVEL TWO'!$O$704 -> 6 | L58: =J58/I58*100 -> 78.571429 | M58: =K58/I58*100 -> 21.428571 | N58: ='FBMS-HND LEVEL TWO'!O711 -> 3 | O58: ='FBMS-HND LEVEL TWO'!P711 -> 3 | P58: ='FBMS-HND LEVEL TWO'!Q711 -> 7 | Q58: ='FBMS-HND LEVEL TWO'!R711 -> 1 | R58: ='FBMS-HND LEVEL TWO'!S711 -> 8 | S58: ='FBMS-HND LEVEL TWO'!T711 -> 0 | T58: ='FBMS-HND LEVEL TWO'!U711 -> 3 | U58: ='FBMS-HND LEVEL TWO'!V711 -> 3 | V58: =SUM(N58:U58) -> 28
A59: 7 | B59: ='[1]level two'!$C$364 -> ACC 2104H | C59: ='[1]level two'!$C$365 -> Company Accounting | D59: 3 | E59: C | F59: ='[1]level two'!$C$367 -> Mr. Mforsah Roger | H59: ='FBMS-HND LEVEL TWO'!$O$753 -> 23 | I59: ='FBMS-HND LEVEL TWO'!$O$754 -> 20 | J59: ='FBMS-HND LEVEL TWO'!$O$756 -> 17 | K59: ='FBMS-HND LEVEL TWO'!$O$758 -> 3 | L59: =J59/I59*100 -> 85 | M59: =K59/I59*100 -> 15 | N59: ='FBMS-HND LEVEL TWO'!O765 -> 3 | O59: ='FBMS-HND LEVEL TWO'!P765 -> 2 | P59: ='FBMS-HND LEVEL TWO'!Q765 -> 4 | Q59: ='FBMS-HND LEVEL TWO'!R765 -> 3 | R59: ='FBMS-HND LEVEL TWO'!S765 -> 5 | S59: ='FBMS-HND LEVEL TWO'!T765 -> 0 | T59: ='FBMS-HND LEVEL TWO'!U765 -> 1 | U59: ='FBMS-HND LEVEL TWO'!V765 -> 2 | V59: =SUM(N59:U59) -> 20
A60: 8 | B60: ='[1]level two'!$C$395 -> ACC 2101H | C60: ='[1]level two'!$C$396 -> Computer Asisted Accounting II | D60: ='[1]level two'!$C$397 -> 3 | E60: C | F60: Mr.Ngondo Charles | H60: ='FBMS-HND LEVEL TWO'!$O$797 -> 21 | I60: ='FBMS-HND LEVEL TWO'!$O$798 -> 21 | J60: ='FBMS-HND LEVEL TWO'!$O$800 -> 19 | K60: ='FBMS-HND LEVEL TWO'!$O$802 -> 2 | L60: =J60/I60*100 -> 90.47619 | M60: =K60/I60*100 -> 9.5238095 | N60: ='FBMS-HND LEVEL TWO'!O809 -> 8 | O60: ='FBMS-HND LEVEL TWO'!P809 -> 4 | P60: ='FBMS-HND LEVEL TWO'!Q809 -> 6 | Q60: ='FBMS-HND LEVEL TWO'!R809 -> 0 | R60: ='FBMS-HND LEVEL TWO'!S809 -> 1 | S60: ='FBMS-HND LEVEL TWO'!T809 -> 1 | T60: ='FBMS-HND LEVEL TWO'!U809 -> 0 | U60: ='FBMS-HND LEVEL TWO'!V809 -> 1 | V60: =SUM(N60:U60) -> 21
C61: TOTAL/ AVERAGE | H61: =SUM(H53:H60) -> 316 | I61: =SUM(I53:I60) -> 310 | J61: =SUM(J53:J60) -> 252 | K61: =SUM(K53:K60) -> 58 | L61: =J61/I61*100 -> 81.290323 | M61: =K61/I61*100 -> 18.709677 | N61: =SUM(N53:N60) -> 43 | O61: =SUM(O53:O60) -> 50 | P61: =SUM(P53:P60) -> 86 | Q61: =SUM(Q53:Q60) -> 27 | R61: =SUM(R53:R60) -> 46 | S61: =SUM(S53:S60) -> 6 | T61: =SUM(T53:T60) -> 16 | U61: =SUM(U53:U60) -> 36 | V61: =SUM(N61:U61) -> 310
B62: CV = Credit Value; ST = Status (C = Compulsory; E = Elective); CR = Candidates Registered; CE = Candidates Examined; % CC = Course Coverage; The % Pass is based on CE (Candidates who completed the course by writing the final examination.
...

Sheet RESULTS
I1: Catholic University of Cameroon, CATUC, Bamenda
I2: Faculty of Business and Management Sciences-HND
I3: DEPARTMENT : HND /LEVEL ONE | AJ3: Level One
G4: LEVEL ONE | I4: First Semester CA/ Examination, 2023-2024
A5: S/N | B5: Mat No. | C5: Name of Student | D5: MAT No. | O5: Courses | AI5: Courses
